Workbook

Sheet  GDP CEE Oct 2025
A1: GDP, current prices (Billions of U.S. dollars) | B1: 2010 | C1: 2011 | D1: 2012 | E1: 2013 | F1: 2014 | G1: 2015 | H1: 2016 | I1: 2017 | J1: 2018 | K1: 2019 | L1: 2020 | M1: 2021 | N1: 2022 | O1: 2023 | P1: 2024 | Q1: 2025 | R1: 2026 | S1: 2027 | T1: 2028 | U1: 2029 | V1: 2030
A2: Albania | B2: 11.937 | C2: 12.899 | D2: 12.324 | E2: 12.784 | F2: 13.246 | G2: 11.389 | H2: 11.862 | I2: 13.053 | J2: 15.38 | K2: 15.582 | L2: 15.271 | M2: 17.985 | N2: 19.189 | O2: 23.633 | P2: 27.084 | Q2: 29.939 | R2: 32.411 | S2: 34.208 | T2: 36.358 | U2: 38.657 | V2: 41.115
A3: Armenia | B3: 9.26 | C3: 10.142 | D3: 10.619 | E3: 11.121 | F3: 11.61 | G3: 10.553 | H3: 10.546 | I3: 11.527 | J3: 12.458 | K3: 13.619 | L3: 12.642 | M3: 13.879 | N3: 19.514 | O3: 24.186 | P3: 25.955 | Q3: 27.859 | R3: 29.082 | S3: 31.454 | T3: 33.676 | U3: 35.934 | V3: 38.388
A4: Azerbaijan | B4: 52.909 | C4: 65.952 | D4: 69.684 | E4: 74.164 | F4: 75.235 | G4: 52.997 | H4: 37.83 | I4: 41.375 | J4: 47.113 | K4: 48.174 | L4: 42.693 | M4: 54.825 | N4: 78.807 | O4: 72.428 | P4: 74.316 | Q4: 76.39 | R4: 80.024 | S4: 84.547 | T4: 89.615 | U4: 95.052 | V4: 100.823
A5: Bosnia and Herzegovina | B5: 17.207 | C5: 18.665 | D5: 17.237 | E5: 18.184 | F5: 18.588 | G5: 16.413 | H5: 17.124 | I5: 18.363 | J5: 20.504 | K5: 20.485 | L5: 20.264 | M5: 23.688 | N5: 24.581 | O5: 27.606 | P5: 29.614 | Q5: 33.237 | R5: 36.239 | S5: 38.082 | T5: 40.004 | U5: 42.005 | V5: 44.106
A6: Bulgaria | B6: 50.69 | C6: 57.682 | D6: 54.297 | E6: 55.82 | F6: 57.081 | G6: 50.766 | H6: 53.929 | I6: 59.288 | J6: 66.318 | K6: 68.639 | L6: 70.658 | M6: 84.477 | N6: 90.719 | O6: 102.434 | P6: 112.232 | Q6: 127.924 | R6: 142.203 | S6: 151.081 | T6: 159.772 | U6: 168.285 | V6: 177.26
A7: Croatia | B7: 59.032 | C7: 62.889 | D7: 57.585 | E7: 59.854 | F7: 59.628 | G7: 51.012 | H7: 52.64 | I7: 56.166 | J7: 61.694 | K7: 61.472 | L7: 57.919 | M7: 69.055 | N7: 71.26 | O7: 84.429 | P7: 92.643 | Q7: 103.901 | R7: 113.132 | S7: 118.4 | T7: 123.879 | U7: 129.666 | V7: 135.725
A8: Czech Republic | B8: 211.169 | C8: 231.429 | D8: 210.363 | E8: 213.024 | F8: 210.911 | G8: 189.108 | H8: 198.161 | I8: 221.564 | J8: 251.992 | K8: 256.794 | L8: 251.11 | M8: 290.973 | N8: 301.831 | O8: 345.059 | P8: 347.034 | Q8: 383.384 | R8: 417.134 | S8: 433.435 | T8: 450.45 | U8: 467.644 | V8: 485.675
A9: Estonia | B9: 19.569 | C9: 23.3 | D9: 23.252 | E9: 25.451 | F9: 27.063 | G9: 23.314 | H9: 24.554 | I9: 27.46 | J9: 31.237 | K9: 31.877 | L9: 31.795 | M9: 37.226 | N9: 38.257 | O9: 41.482 | P9: 43.117 | Q9: 46.763 | R9: 51.036 | S9: 53.619 | T9: 56.106 | U9: 58.687 | V9: 61.302
A10: Georgia | B10: 12.425 | C10: 15.475 | D10: 16.894 | E10: 17.516 | F10: 17.966 | G10: 15.223 | H10: 15.445 | I10: 16.472 | J10: 17.905 | K10: 17.645 | L10: 16.013 | M10: 18.849 | N10: 24.985 | O10: 30.778 | P10: 33.775 | Q10: 37.403 | R10: 40.177 | S10: 42.408 | T10: 44.723 | U10: 47.202 | V10: 49.802
A11: Hungary | B11: 131.899 | C11: 141.713 | D11: 128.47 | E11: 135.646 | F11: 141.129 | G11: 125.244 | H11: 128.984 | I11: 143.335 | J11: 161.185 | K11: 164.927 | L11: 158.468 | M11: 183.283 | N11: 178.321 | O11: 214.098 | P11: 223.06 | Q11: 247.759 | R11: 269.916 | S11: 284.122 | T11: 298.583 | U11: 314.311 | V11: 331.126
A12: Latvia | B12: 23.509 | C12: 26.832 | D12: 27.136 | E12: 29.157 | F12: 30.285 | G12: 26.347 | H12: 27.11 | I12: 29.381 | J12: 33.263 | K12: 33.103 | L12: 33.353 | M12: 38.209 | N12: 38.045 | O12: 42.584 | P12: 43.508 | Q12: 47.88 | R12: 52.248 | S12: 55.114 | T12: 57.86 | U12: 60.722 | V12: 63.664
... A21: Slovenia | B21: 47.832 | C21: 51.19 | D21: 46.196 | E21: 47.868 | F21: 49.527 | G21: 42.714 | H21: 44.279 | I21: 48.136 | J21: 53.713 | K21: 53.916 | L21: 53.342 | M21: 61.582 | N21: 59.946 | O21: 69.275 | P21: 72.95 | Q21: 79.221 | R21: 85.738 | S21: 89.576 | T21: 93.612 | U21: 97.719 | V21: 102.031
A22: TOTAL | B22: =SUM(B2:B21) -> 1487.356 | C22: =SUM(C2:C21) -> 1656.446 | D22: =SUM(D2:D21) -> 1556.598 | E22: =SUM(E2:E21) -> 1629.263 | F22: =SUM(F2:F21) -> 1679.126 | G22: =SUM(G2:G21) -> 1466.575 | H22: =SUM(H2:H21) -> 1479.206 | I22: =SUM(I2:I21) -> 1640.462 | ... V22: =SUM(V2:V21) -> 4073.355
A24: Real GDP growth (Annual percent change) | B24: 2010 | C24: 2011 | D24: 2012 | E24: 2013 | F24: 2014 | G24: 2015 | H24: 2016 | I24: 2017 | J24: 2018 | K24: 2019 | L24: 2020 | M24: 2021 | N24: 2022 | O24: 2023 | P24: 2024 | Q24: 2025 | R24: 2026 | S24: 2027 | T24: 2028 | U24: 2029 | V24: 2030
A25: Albania | B25: 3.7 | C25: 2.5 | D25: 1.4 | E25: 1 | F25: 1.8 | G25: 2.2 | H25: 3.9 | I25: 3.3 | J25: 3.7 | K25: 2.1 | L25: -3.3 | M25: 9 | N25: 4.8 | O25: 4 | P25: 4 | Q25: 3.4 | R25: 3.6 | S25: 3.5 | T25: 3.5 | U25: 3.5 | V25: 3.5
A26: Armenia | B26: 2.2 | C26: 4.7 | D26: 7.1 | E26: 3.4 | F26: 3.6 | G26: 3.3 | H26: 0.2 | I26: 7.5 | J26: 5.2 | K26: 7.6 | L26: -7.1 | M26: 5.8 | N26: 12.6 | O26: 8.3 | P26: 5.9 | Q26: 4.8 | R26: 4.9 | S26: 5.5 | T26: 4.8 | U26: 4.5 | V26: 4.5
A27: Azerbaijan | B27: 5 | C27: 0.1 | D27: 2.2 | E27: 5.8 | F27: 2.8 | G27: 1.1 | H27: -3.1 | I27: 0.2 | J27: 1.5 | K27: 2.5 | L27: -4.2 | M27: 5.6 | N27: 4.7 | O27: 1.4 | P27: 4.1 | Q27: 3 | R27: 2.5 | S27: 2.5 | T27: 2.5 | U27: 2.5 | V27: 2.5
A28: Bosnia and Herzegovina | B28: 0.9 | C28: 1 | D28: -0.8 | E28: 2.3 | F28: 1.2 | G28: 4.3 | H28: 3.2 | I28: 3.2 | J28: 3.8 | K28: 2.9 | L28: -3 | M28: 7.4 | N28: 4.2 | O28: 2 | P28: 3 | Q28: 2.4 | R28: 2.7 | S28: 3 | T28: 3 | U28: 3 | V28: 3
A29: Bulgaria | B29: 1.6 | C29: 2.1 | D29: 0.7 | E29: -0.5 | F29: 0.9 | G29: 3.4 | H29: 3 | I29: 2.7 | J29: 2.5 | K29: 3.8 | L29: -3.2 | M29: 7.8 | N29: 4 | O29: 1.9 | P29: 2.8 | Q29: 3 | R29: 3.1 | S29: 2.8 | T29: 2.7 | U29: 2.6 | V29: 2.6
A30: Croatia | B30: -1.3 | C30: -0.1 | D30: -2.3 | E30: -0.1 | F30: -0.6 | G30: 2.3 | H30: 3.5 | I30: 3.3 | J30: 2.9 | K30: 3.1 | L30: -8.3 | M30: 12.6 | N30: 7.3 | O30: 3.3 | P30: 3.9 | Q30: 3.1 | R30: 2.7 | S30: 2.6 | T30: 2.6 | U30: 2.5 | V30: 2.5
A31: Czech Republic | B31: 2.7 | C31: 1.8 | D31: -0.8 | E31: 0 | F31: 2.2 | G31: 5 | H31: 2.6 | I31: 5.2 | J31: 2.8 | K31: 3.6 | L31: -5.3 | M31: 4 | N31: 2.8 | O31: 0 | P31: 1.2 | Q31: 2.3 | R31: 2 | S31: 2 | T31: 2 | U31: 2 | V31: 2
A32: Estonia | B32: 2.4 | C32: 7.6 | D32: 3.7 | E32: 1.8 | F32: 3.3 | G32: 1.8 | H32: 3.1 | I32: 5.6 | J32: 3.7 | K32: 3.7 | L32: -2.9 | M32: 8.3 | N32: -1.2 | O32: -2.7 | P32: -0.1 | Q32: 0.5 | R32: 1.5 | S32: 1.8 | T32: 1.8 | U32: 1.8 | V32: 1.7
A33: Georgia | B33: 6.9 | C33: 7.9 | D33: 6.6 | E33: 5.1 | F33: 4.1 | G33: 3.4 | H33: 3.4 | I33: 5.2 | J33: 6.1 | K33: 5.4 | L33: -6.3 | M33: 10.6 | N33: 11 | O33: 7.8 | P33: 9.4 | Q33: 7.2 | R33: 5.3 | S33: 5 | T33: 5 | U33: 5 | V33: 5
A34: Hungary | B34: 1.1 | C34: 1.9 | D34: -1.3 | E34: 2 | F34: 4.3 | G34: 3.7 | H34: 2.4 | I34: 4.1 | J34: 5.6 | K34: 5.1 | L34: -4.3 | M34: 7.2 | N34: 4.3 | O34: -0.8 | P34: 0.5 | Q34: 0.6 | R34: 2.1 | S34: 2.3 | T34: 2.4 | U34: 2.5 | V34: 2.5
A35: Latvia | B35: -3.7 | C35: 3 | D35: 7.3 | E35: 2.1 | F35: 2.1 | G35: 3.8 | H35: 2.6 | I35: 3.4 | J35: 4.3 | K35: 0.7 | L35: -3.5 | M35: 6.9 | N35: 1.8 | O35: 2.9 | P35: -0.4 | Q35: 1 | R35: 2.2 | S35: 2.4 | T35: 2.4 | U35: 2.4 | V35: 2.4
... A46: Indexation | B46: 2010 | C46: 2011 | D46: 2012 | E46: 2013 | F46: 2014 | G46: 2015 | H46: 2016 | I46: 2017 | J46: 2018 | K46: 2019 | L46: 2020 | M46: 2021 | N46: 2022 | O46: 2023 | P46: 2024 | Q46: 2025 | R46: 2026 | S46: 2027 | T46: 2028 | U46: 2029 | V46: 2030
A48: Albania | B48: 100 | C48: =B48*(1+(C25/100)) -> 102.5 | D48: =C48*(1+(D25/100)) -> 103.935 | E48: =D48*(1+(E25/100)) -> 104.97435 | F48: =E48*(1+(F25/100)) -> 106.86389 | G48: =F48*(1+(G25/100)) -> 109.21489 | H48: =G48*(1+(H25/100)) -> 113.47427 | I48: =H48*(1+(I25/100)) -> 117.21893 | J48: =I48*(1+(J25/100)) -> 121.55603 | ... V48: =U48*(1+(V25/100)) -> 182.27406
A49: Armenia | B49: 100 | C49: =B49*(1+(C26/100)) -> 104.7 | D49: =C49*(1+(D26/100)) -> 112.1337 | E49: =D49*(1+(E26/100)) -> 115.94625 | F49: =E49*(1+(F26/100)) -> 120.12031 | G49: =F49*(1+(G26/100)) -> 124.08428 | H49: =G49*(1+(H26/100)) -> 124.33245 | I49: =H49*(1+(I26/100)) -> 133.65738 | J49: =I49*(1+(J26/100)) -> 140.60757 | ... V49: =U49*(1+(V26/100)) -> 254.89907
A50: Azerbaijan | B50: 100 | C50: =B50*(1+(C27/100)) -> 100.1 | D50: =C50*(1+(D27/100)) -> 102.3022 | E50: =D50*(1+(E27/100)) -> 108.23573 | F50: =E50*(1+(F27/100)) -> 111.26633 | G50: =F50*(1+(G27/100)) -> 112.49026 | H50: =G50*(1+(H27/100)) -> 109.00306 | I50: =H50*(1+(I27/100)) -> 109.22107 | J50: =I50*(1+(J27/100)) -> 110.85938 | ... V50: =U50*(1+(V27/100)) -> 148.05315
A51: Bosnia and Herzegovina | B51: 100 | C51: =B51*(1+(C28/100)) -> 101 | D51: =C51*(1+(D28/100)) -> 100.192 | E51: =D51*(1+(E28/100)) -> 102.49642 | F51: =E51*(1+(F28/100)) -> 103.72637 | G51: =F51*(1+(G28/100)) -> 108.18661 | H51: =G51*(1+(H28/100)) -> 111.64858 | I51: =H51*(1+(I28/100)) -> 115.22133 | J51: =I51*(1+(J28/100)) -> 119.59974 | ... V51: =U51*(1+(V28/100)) -> 166.12923
A52: Bulgaria | B52: 100 | C52: =B52*(1+(C29/100)) -> 102.1 | D52: =C52*(1+(D29/100)) -> 102.8147 | E52: =D52*(1+(E29/100)) -> 102.30063 | F52: =E52*(1+(F29/100)) -> 103.22133 | G52: =F52*(1+(G29/100)) -> 106.73086 | H52: =G52*(1+(H29/100)) -> 109.93278 | I52: =H52*(1+(I29/100)) -> 112.90097 | J52: =I52*(1+(J29/100)) -> 115.72349 | ... V52: =U52*(1+(V29/100)) -> 161.16392
A53: Croatia | B53: 100 | C53: =B53*(1+(C30/100)) -> 99.9 | D53: =C53*(1+(D30/100)) -> 97.6023 | E53: =D53*(1+(E30/100)) -> 97.504698 | F53: =E53*(1+(F30/100)) -> 96.91967 | G53: =F53*(1+(G30/100)) -> 99.148822 | H53: =G53*(1+(H30/100)) -> 102.61903 | I53: =H53*(1+(I30/100)) -> 106.00546 | J53: =I53*(1+(J30/100)) -> 109.07962 | ... V53: =U53*(1+(V30/100)) -> 156.60194
A54: Czech Republic | B54: 100 | C54: =B54*(1+(C31/100)) -> 101.8 | D54: =C54*(1+(D31/100)) -> 100.9856 | E54: =D54*(1+(E31/100)) -> 100.9856 | F54: =E54*(1+(F31/100)) -> 103.20728 | G54: =F54*(1+(G31/100)) -> 108.36765 | H54: =G54*(1+(H31/100)) -> 111.18521 | I54: =H54*(1+(I31/100)) -> 116.96684 | J54: =I54*(1+(J31/100)) -> 120.24191 | ... V54: =U54*(1+(V31/100)) -> 144.16142
A55: Estonia | B55: 100 | C55: =B55*(1+(C32/100)) -> 107.6 | D55: =C55*(1+(D32/100)) -> 111.5812 | E55: =D55*(1+(E32/100)) -> 113.58966 | F55: =E55*(1+(F32/100)) -> 117.33812 | G55: =F55*(1+(G32/100)) -> 119.45021 | H55: =G55*(1+(H32/100)) -> 123.15316 | I55: =H55*(1+(I32/100)) -> 130.04974 | J55: =I55*(1+(J32/100)) -> 134.86158 | ... V55: =U55*(1+(V32/100)) -> 154.57753
A56: Georgia | B56: 100 | C56: =B56*(1+(C33/100)) -> 107.9 | D56: =C56*(1+(D33/100)) -> 115.0214 | E56: =D56*(1+(E33/100)) -> 120.88749 | F56: =E56*(1+(F33/100)) -> 125.84388 | G56: =F56*(1+(G33/100)) -> 130.12257 | H56: =G56*(1+(H33/100)) -> 134.54674 | I56: =H56*(1+(I33/100)) -> 141.54317 | J56: =I56*(1+(J33/100)) -> 150.1773 | ... V56: =U56*(1+(V33/100)) -> 294.63141
A57: Hungary | B57: 100 | C57: =B57*(1+(C34/100)) -> 101.9 | D57: =C57*(1+(D34/100)) -> 100.5753 | E57: =D57*(1+(E34/100)) -> 102.58681 | F57: =E57*(1+(F34/100)) -> 106.99804 | G57: =F57*(1+(G34/100)) -> 110.95697 | H57: =G57*(1+(H34/100)) -> 113.61993 | I57: =H57*(1+(I34/100)) -> 118.27835 | J57: =I57*(1+(J34/100)) -> 124.90194 | ... V57: =U57*(1+(V34/100)) -> 158.30247
A58: Latvia | B58: 100 | C58: =B58*(1+(C35/100)) -> 103 | D58: =C58*(1+(D35/100)) -> 110.519 | E58: =D58*(1+(E35/100)) -> 112.8399 | F58: =E58*(1+(F35/100)) -> 115.20954 | G58: =F58*(1+(G35/100)) -> 119.5875 | H58: =G58*(1+(H35/100)) -> 122.69677 | I58: =H58*(1+(I35/100)) -> 126.86846 | J58: =I58*(1+(J35/100)) -> 132.32381 | ... V58: =U58*(1+(V35/100)) -> 162.76727
A59: Lithuania | B59: 100 | C59: =B59*(1+(C36/100)) -> 106.3 | D59: =C59*(1+(D36/100)) -> 110.9772 | E59: =D59*(1+(E36/100)) -> 115.52727 | F59: =E59*(1+(F36/100)) -> 119.9173 | G59: =F59*(1+(G36/100)) -> 123.27499 | H59: =G59*(1+(H36/100)) -> 126.48014 | I59: =H59*(1+(I36/100)) -> 132.4247 | J59: =I59*(1+(J36/100)) -> 138.78109 | ... V59: =U59*(1+(V36/100)) -> 189.85838
... A67: Slovenia | B67: 100 | C67: =B67*(1+(C44/100)) -> 100.7 | D67: =C67*(1+(D44/100)) -> 97.7797 | E67: =D67*(1+(E44/100)) -> 96.997462 | F67: =E67*(1+(F44/100)) -> 99.713391 | G67: =F67*(1+(G44/100)) -> 102.10651 | H67: =G67*(1+(H44/100)) -> 105.16971 | I67: =H67*(1+(I44/100)) -> 110.63853 | J67: =I67*(1+(J44/100)) -> 115.50663 | ... V67: =U67*(1+(V44/100)) -> 151.00397
...

Sheet GDP WE Oct 2025
A1: GDP, current prices (Billions of U.S. dollars) | B1: 2010 | C1: 2011 | D1: 2012 | E1: 2013 | F1: 2014 | G1: 2015 | H1: 2016 | I1: 2017 | J1: 2018 | K1: 2019 | L1: 2020 | M1: 2021 | N1: 2022 | O1: 2023 | P1: 2024 | Q1: 2025 | R1: 2026 | S1: 2027 | T1: 2028 | U1: 2029 | V1: 2030
A2: Austria | B2: 390.146 | C2: 428.879 | D2: 407.008 | E2: 426.587 | F2: 438.669 | G2: 379.584 | H2: 393.579 | I2: 414.78 | J2: 452.787 | K2: 443.033 | L2: 434.05 | M2: 480.786 | N2: 472.145 | O2: 511.833 | P2: 523.956 | Q2: 566.456 | R2: 604.198 | S2: 625.678 | T2: 646.073 | U2: 666.33 | V2: 685.248
A3: Belgium | B3: 481.949 | C3: 527.106 | D3: 498.731 | E3: 524.106 | F3: 538.127 | G3: 461.091 | H3: 474.141 | I3: 500.733 | J3: 542.885 | K3: 536.787 | L3: 529.269 | M3: 598.92 | N3: 594.081 | O3: 644.84 | P3: 664.365 | Q3: 716.98 | R3: 761.174 | S3: 780.384 | T3: 802.019 | U3: 824.347 | V3: 849.306
A4: Denmark | B4: 322.346 | C4: 344.316 | D4: 326.793 | E4: 344.631 | F4: 352.833 | G4: 301.759 | H4: 312.182 | I4: 331.611 | J4: 355.293 | K4: 345.402 | L4: 355.631 | M4: 406.11 | N4: 400.115 | O4: 404.652 | P4: 424.525 | Q4: 459.612 | R4: 500.051 | S4: 521.566 | T4: 542.455 | U4: 563.668 | V4: 585.835
A5: Finland | B5: 249.633 | C5: 275.079 | D5: 257.606 | E5: 270.272 | F5: 273.549 | G5: 233.234 | H5: 238.712 | I5: 253.757 | J5: 273.993 | K5: 267.044 | L5: 269.784 | M5: 294.419 | N5: 280.474 | O5: 295.135 | P5: 298.607 | Q5: 314.724 | R5: 335.534 | S5: 346.309 | T5: 356.83 | U5: 368.667 | V5: 381.547
A6: France | B6: 2648.391 | C6: 2869.903 | D6: 2684.706 | E6: 2816.119 | F6: 2861.973 | G6: 2442.731 | H6: 2469.726 | I6: 2587.955 | J6: 2782.838 | K6: 2723.094 | L6: 2645.806 | M6: 2968.405 | N6: 2796.987 | O6: 3061.093 | P6: 3160.902 | Q6: 3361.557 | R6: 3558.562 | S6: 3661.084 | T6: 3772.836 | U6: 3890.001 | V6: 4009.171
A7: Germany | B7: 3469.925 | C7: 3822.903 | D7: 3598.761 | E7: 3807.079 | F7: 3965.893 | G7: 3425.446 | H7: 3535.812 | I7: 3764.023 | J7: 4057.272 | K7: 3960.332 | L7: 3938.244 | M7: 4358.147 | N7: 4204.327 | O7: 4563.523 | P7: 4684.182 | Q7: 5013.574 | R7: 5328.184 | S7: 5498.618 | T7: 5674.354 | U7: 5848.295 | V7: 6013.749
A8: Greece | B8: 296.66 | C8: 283.178 | D8: 238.992 | E8: 236.56 | F8: 233.972 | G8: 194.587 | H8: 193.044 | I8: 200.31 | J8: 213.396 | K8: 207.329 | L8: 191.21 | M8: 218.449 | N8: 219.053 | O8: 243.569 | P8: 257.067 | Q8: 282.019 | R8: 304.838 | S8: 316.711 | T8: 327.921 | U8: 339.478 | V8: 351.607
A9: Ireland | B9: 221.914 | C9: 240.934 | D9: 227.066 | E9: 242.928 | F9: 266.559 | G9: 302.133 | H9: 305.347 | I9: 348.232 | J9: 395.96 | K9: 407.256 | L9: 435.659 | M9: 530.747 | N9: 548.773 | O9: 567.537 | P9: 608.974 | Q9: 708.771 | R9: 750.112 | S9: 779.063 | T9: 810.885 | U9: 844.921 | V9: 880.832
A10: Italy | B10: 2146.687 | C10: 2306.568 | D10: 2099.259 | E10: 2153.259 | F10: 2173.815 | G10: 1845.615 | H10: 1886.59 | I10: 1970.027 | J10: 2100.387 | K10: 2019.831 | L10: 1905.956 | M10: 2180.657 | N10: 2105.723 | O10: 2305.27 | P10: 2372.059 | Q10: 2543.677 | R10: 2701.544 | S10: 2764.053 | T10: 2833.607 | U10: 2908.154 | V10: 2985.05
A11: Luxembourg | B11: 56.26 | C11: 61.685 | D11: 59.814 | E11: 65.204 | F11: 68.822 | G11: 60.078 | H11: 62.2 | I11: 65.689 | J11: 71.118 | K11: 69.88 | L11: 73.612 | M11: 86.444 | N11: 80.865 | O11: 88.815 | P11: 93.252 | Q11: 100.642 | R11: 107.758 | S11: 112.169 | T11: 116.867 | U11: 121.716 | V11: 126.829
A12: Malta | B12: 9.104 | C12: 9.788 | D12: 9.616 | E12: 10.797 | F12: 11.891 | G12: 11.342 | H12: 12.022 | I12: 14.156 | J12: 16.161 | K12: 16.34 | L12: 16.392 | M12: 19.753 | N12: 18.943 | O12: 22.617 | P12: 24.964 | Q12: 27.745 | R12: 30.437 | S12: 32.211 | T12: 34.114 | U12: 36.158 | V12: 38.339
... A19: United Kingdom | B19: 2487.924 | C19: 2664.719 | D19: 2707.571 | E19: 2786.665 | F19: 3066.304 | G19: 2928.558 | H19: 2699.086 | I19: 2682.384 | J19: 2875.024 | K19: 2853.074 | L19: 2698.705 | M19: 3144.079 | N19: 3125.404 | O19: 3371.118 | P19: 3644.636 | Q19: 3958.78 | R19: 4225.639 | S19: 4441.871 | T19: 4673.359 | U19: 4928.634 | V19: 5199.779
A20: TOTAL | B20: =SUM(B2:B19) -> 16824.034 | C20: =SUM(C2:C19) -> 18268.485 | D20: =SUM(D2:D19) -> 17259.719 | E20: =SUM(E2:E19) -> 17973.982 | F20: =SUM(F2:F19) -> 18571.063 | G20: =SUM(G2:G19) -> 16350.902 | H20: =SUM(H2:H19) -> 16400.088 | I20: =SUM(I2:I19) -> 17156.088 | ... V20: =SUM(V2:V19) -> 29227.943
A22: Real GDP growth (Annual percent change) | B22: 2010 | C22: 2011 | D22: 2012 | E22: 2013 | F22: 2014 | G22: 2015 | H22: 2016 | I22: 2017 | J22: 2018 | K22: 2019 | L22: 2020 | M22: 2021 | N22: 2022 | O22: 2023 | P22: 2024 | Q22: 2025 | R22: 2026 | S22: 2027 | T22: 2028 | U22: 2029 | V22: 2030
A23: Austria | B23: 1.8 | C23: 2.9 | D23: 0.6 | E23: -0.3 | F23: 0.8 | G23: 1.3 | H23: 2.1 | I23: 2.3 | J23: 2.5 | K23: 1.8 | L23: -6.3 | M23: 4.8 | N23: 5.3 | O23: -1 | P23: -1 | Q23: 0.3 | R23: 0.8 | S23: 1.6 | T23: 1.3 | U23: 1 | V23: 0.7
A24: Belgium | B24: 2.7 | C24: 1.9 | D24: 0.2 | E24: 0.3 | F24: 1.8 | G24: 1.5 | H24: 1.2 | I24: 1.5 | J24: 1.9 | K24: 2.4 | L24: -4.8 | M24: 6.2 | N24: 4.3 | O24: 1.2 | P24: 1 | Q24: 1.1 | R24: 1 | S24: 1.3 | T24: 1.2 | U24: 1.3 | V24: 1.3
A25: Denmark | B25: 1.6 | C25: 1.3 | D25: 0 | E25: 1.4 | F25: 1.3 | G25: 2.1 | H25: 3.1 | I25: 3.1 | J25: 1.9 | K25: 1.7 | L25: -1.8 | M25: 6.5 | N25: 0.4 | O25: 0.6 | P25: 3.5 | Q25: 1.8 | R25: 2.2 | S25: 1.6 | T25: 1.5 | U25: 1.5 | V25: 1.5
A26: Finland | B26: 3.2 | C26: 2.4 | D26: -1.5 | E26: -1 | F26: -0.5 | G26: 0.5 | H26: 2.6 | I26: 3.3 | J26: 1.2 | K26: 1.3 | L26: -2.5 | M26: 2.7 | N26: 0.8 | O26: -0.9 | P26: 0.4 | Q26: 0.5 | R26: 1.3 | S26: 1.3 | T26: 1.3 | U26: 1.2 | V26: 1.2
A27: France | B27: 1.8 | C27: 2.5 | D27: 0.2 | E27: 0.9 | F27: 1 | G27: 1 | H27: 0.7 | I27: 2.3 | J27: 1.6 | K27: 2.1 | L27: -7.6 | M27: 6.8 | N27: 2.8 | O27: 1.6 | P27: 1.1 | Q27: 0.7 | R27: 0.9 | S27: 1.2 | T27: 1.3 | U27: 1.2 | V27: 1.2
A28: Germany | B28: 4.1 | C28: 3.8 | D28: 0.5 | E28: 0.4 | F28: 2.2 | G28: 1.7 | H28: 2.2 | I28: 2.8 | J28: 1.1 | K28: 1 | L28: -4.1 | M28: 3.9 | N28: 1.8 | O28: -0.9 | P28: -0.5 | Q28: 0.2 | R28: 0.9 | S28: 1.5 | T28: 1.2 | U28: 1 | V28: 0.7
A29: Greece | B29: -5.7 | C29: -9.9 | D29: -8.3 | E29: -2.3 | F29: 0.8 | G29: -0.2 | H29: 0 | I29: 1.5 | J29: 2.1 | K29: 2.3 | L29: -9.2 | M29: 8.7 | N29: 5.7 | O29: 2.3 | P29: 2.3 | Q29: 2 | R29: 2 | S29: 1.5 | T29: 1.6 | U29: 1.6 | V29: 1.6
A30: Ireland | B30: 1.7 | C30: 1.6 | D30: -0.4 | E30: 2.2 | F30: 9.4 | G30: 24.6 | H30: 1.2 | I30: 10.1 | J30: 7.7 | K30: 5 | L30: 7.2 | M30: 16.3 | N30: 7.5 | O30: -2.5 | P30: 2.6 | Q30: 9.1 | R30: 1.3 | S30: 2.5 | T30: 2.4 | U30: 2.3 | V30: 2.3
A31: Italy | B31: 1.5 | C31: 0.7 | D31: -3.1 | E31: -1.8 | F31: 0 | G31: 0.9 | H31: 1.2 | I31: 1.6 | J31: 0.8 | K31: 0.4 | L31: -8.9 | M31: 8.9 | N31: 4.8 | O31: 0.7 | P31: 0.7 | Q31: 0.5 | R31: 0.8 | S31: 0.6 | T31: 0.7 | U31: 0.7 | V31: 0.7
A32: Luxembourg | B32: 3.8 | C32: 1 | D32: 1.6 | E32: 3.2 | F32: 2.6 | G32: 2.3 | H32: 5 | I32: 1.3 | J32: 1.6 | K32: 2.7 | L32: -0.5 | M32: 6.9 | N32: -1.1 | O32: 0.1 | P32: 0.4 | Q32: 1.2 | R32: 2.1 | S32: 2.3 | T32: 2.2 | U32: 2.1 | V32: 2.1
A33: Malta | B33: 6.2 | C33: 1 | D33: 4.1 | E33: 6.3 | F33: 7.6 | G33: 9.6 | H33: 4.1 | I33: 13 | J33: 7.2 | K33: 4.1 | L33: -3.5 | M33: 13.4 | N33: 2.5 | O33: 10.6 | P33: 6.8 | Q33: 3.9 | R33: 3.9 | S33: 4 | T33: 4 | U33: 4 | V33: 4
... A42: Indexation | B42: 2010 | C42: 2011 | D42: 2012 | E42: 2013 | F42: 2014 | G42: 2015 | H42: 2016 | I42: 2017 | J42: 2018 | K42: 2019 | L42: 2020 | M42: 2021 | N42: 2022 | O42: 2023 | P42: 2024 | Q42: 2025 | R42: 2026 | S42: 2027 | T42: 2028 | U42: 2029 | V42: 2030
A44: Austria | B44: 100 | C44: =B44*(1+(C23/100)) -> 102.9 | D44: =C44*(1+(D23/100)) -> 103.5174 | E44: =D44*(1+(E23/100)) -> 103.20685 | F44: =E44*(1+(F23/100)) -> 104.0325 | G44: =F44*(1+(G23/100)) -> 105.38493 | H44: =G44*(1+(H23/100)) -> 107.59801 | I44: =H44*(1+(I23/100)) -> 110.07276 | J44: =I44*(1+(J23/100)) -> 112.82458 | ... V44: =U44*(1+(V23/100)) -> 123.18749
A45: Belgium | B45: 100 | C45: =B45*(1+(C24/100)) -> 101.9 | D45: =C45*(1+(D24/100)) -> 102.1038 | E45: =D45*(1+(E24/100)) -> 102.41011 | F45: =E45*(1+(F24/100)) -> 104.25349 | G45: =F45*(1+(G24/100)) -> 105.8173 | H45: =G45*(1+(H24/100)) -> 107.0871 | I45: =H45*(1+(I24/100)) -> 108.69341 | J45: =I45*(1+(J24/100)) -> 110.75858 | ... V45: =U45*(1+(V24/100)) -> 131.3126
A46: Denmark | B46: 100 | C46: =B46*(1+(C25/100)) -> 101.3 | D46: =C46*(1+(D25/100)) -> 101.3 | E46: =D46*(1+(E25/100)) -> 102.7182 | F46: =E46*(1+(F25/100)) -> 104.05354 | G46: =F46*(1+(G25/100)) -> 106.23866 | H46: =G46*(1+(H25/100)) -> 109.53206 | I46: =H46*(1+(I25/100)) -> 112.92755 | J46: =I46*(1+(J25/100)) -> 115.07318 | ... V46: =U46*(1+(V25/100)) -> 141.42256
A47: Finland | B47: 100 | C47: =B47*(1+(C26/100)) -> 102.4 | D47: =C47*(1+(D26/100)) -> 100.864 | E47: =D47*(1+(E26/100)) -> 99.85536 | F47: =E47*(1+(F26/100)) -> 99.356083 | G47: =F47*(1+(G26/100)) -> 99.852864 | H47: =G47*(1+(H26/100)) -> 102.44904 | I47: =H47*(1+(I26/100)) -> 105.82986 | J47: =I47*(1+(J26/100)) -> 107.09981 | ... V47: =U47*(1+(V26/100)) -> 116.57262
A48: France | B48: 100 | C48: =B48*(1+(C27/100)) -> 102.5 | D48: =C48*(1+(D27/100)) -> 102.705 | E48: =D48*(1+(E27/100)) -> 103.62934 | F48: =E48*(1+(F27/100)) -> 104.66564 | G48: =F48*(1+(G27/100)) -> 105.71229 | H48: =G48*(1+(H27/100)) -> 106.45228 | I48: =H48*(1+(I27/100)) -> 108.90068 | J48: =I48*(1+(J27/100)) -> 110.64309 | ... V48: =U48*(1+(V27/100)) -> 125.57491
A49: Germany | B49: 100 | C49: =B49*(1+(C28/100)) -> 103.8 | D49: =C49*(1+(D28/100)) -> 104.319 | E49: =D49*(1+(E28/100)) -> 104.73628 | F49: =E49*(1+(F28/100)) -> 107.04047 | G49: =F49*(1+(G28/100)) -> 108.86016 | H49: =G49*(1+(H28/100)) -> 111.25509 | I49: =H49*(1+(I28/100)) -> 114.37023 | J49: =I49*(1+(J28/100)) -> 115.6283 | ... V49: =U49*(1+(V28/100)) -> 123.3731
A50: Greece | B50: 100 | C50: =B50*(1+(C29/100)) -> 90.1 | D50: =C50*(1+(D29/100)) -> 82.6217 | E50: =D50*(1+(E29/100)) -> 80.721401 | F50: =E50*(1+(F29/100)) -> 81.367172 | G50: =F50*(1+(G29/100)) -> 81.204438 | H50: =G50*(1+(H29/100)) -> 81.204438 | I50: =H50*(1+(I29/100)) -> 82.422504 | J50: =I50*(1+(J29/100)) -> 84.153377 | ... V50: =U50*(1+(V29/100)) -> 104.09655
A51: Ireland | B51: 100 | C51: =B51*(1+(C30/100)) -> 101.6 | D51: =C51*(1+(D30/100)) -> 101.1936 | E51: =D51*(1+(E30/100)) -> 103.41986 | F51: =E51*(1+(F30/100)) -> 113.14133 | G51: =F51*(1+(G30/100)) -> 140.97409 | H51: =G51*(1+(H30/100)) -> 142.66578 | I51: =H51*(1+(I30/100)) -> 157.07503 | J51: =I51*(1+(J30/100)) -> 169.1698 | ... V51: =U51*(1+(V30/100)) -> 289.10551
A52: Italy | B52: 100 | C52: =B52*(1+(C31/100)) -> 100.7 | D52: =C52*(1+(D31/100)) -> 97.5783 | E52: =D52*(1+(E31/100)) -> 95.821891 | F52: =E52*(1+(F31/100)) -> 95.821891 | G52: =F52*(1+(G31/100)) -> 96.684288 | H52: =G52*(1+(H31/100)) -> 97.844499 | I52: =H52*(1+(I31/100)) -> 99.410011 | J52: =I52*(1+(J31/100)) -> 100.20529 | ... V52: =U52*(1+(V31/100)) -> 110.38342
A53: Luxembourg | B53: 100 | C53: =B53*(1+(C32/100)) -> 101 | D53: =C53*(1+(D32/100)) -> 102.616 | E53: =D53*(1+(E32/100)) -> 105.89971 | F53: =E53*(1+(F32/100)) -> 108.6531 | G53: =F53*(1+(G32/100)) -> 111.15213 | H53: =G53*(1+(H32/100)) -> 116.70973 | I53: =H53*(1+(I32/100)) -> 118.22696 | J53: =I53*(1+(J32/100)) -> 120.11859 | ... V53: =U53*(1+(V32/100)) -> 146.86889
A54: Malta | B54: 100 | C54: =B54*(1+(C33/100)) -> 101 | D54: =C54*(1+(D33/100)) -> 105.141 | E54: =D54*(1+(E33/100)) -> 111.76488 | F54: =E54*(1+(F33/100)) -> 120.25901 | G54: =F54*(1+(G33/100)) -> 131.80388 | H54: =G54*(1+(H33/100)) -> 137.20784 | I54: =H54*(1+(I33/100)) -> 155.04486 | J54: =I54*(1+(J33/100)) -> 166.20809 | ... V54: =U54*(1+(V33/100)) -> 289.50625
A55: Netherlands | B55: 100 | C55: =B55*(1+(C34/100)) -> 101.8 | D55: =C55*(1+(D34/100)) -> 100.782 | E55: =D55*(1+(E34/100)) -> 100.782 | F55: =E55*(1+(F34/100)) -> 102.39451 | G55: =F55*(1+(G34/100)) -> 104.5448 | H55: =G55*(1+(H34/100)) -> 107.05387 | I55: =H55*(1+(I34/100)) -> 110.05138 | J55: =I55*(1+(J34/100)) -> 112.58256 | ... V55: =U55*(1+(V34/100)) -> 134.28101
... A61: United Kingdom | B61: 100 | C61: =B61*(1+(C40/100)) -> 101.1 | D61: =C61*(1+(D40/100)) -> 102.6165 | E61: =D61*(1+(E40/100)) -> 104.4636 | F61: =E61*(1+(F40/100)) -> 107.80643 | G61: =F61*(1+(G40/100)) -> 110.17817 | H61: =G61*(1+(H40/100)) -> 112.27156 | I61: =H61*(1+(I40/100)) -> 115.30289 | J61: =I61*(1+(J40/100)) -> 116.91713 | ... V61: =U61*(1+(V40/100)) -> 133.67158
...

Sheet Population
A1: POPULATION | I1: 40543 | J1: =EOMONTH(I1,12) -> 40908 | K1: =EOMONTH(J1,12) -> 41274 | L1: =EOMONTH(K1,12) -> 41639 | M1: =EOMONTH(L1,12) -> 42004 | N1: =EOMONTH(M1,12) -> 42369 | O1: =EOMONTH(N1,12) -> 42735 | P1: =EOMONTH(O1,12) -> 43100 | Q1: =EOMONTH(P1,12) -> 43465 | ... AC1: =EOMONTH(AB1,12) -> 47848
A2: Albania | C2: ABIA | D2: =UPPER(LEFT(A2,3)) -> ALB | F2: =C2&"TBSP Index" -> ABIATBSP Index | I2: 2986952 | J2: 2994667 | K2: 3002859 | L2: 3011405 | M2: 3020209 | N2: 3029278 | O2: 3038594 | P2: 3047987 | Q2: 3057220 | R2: 3066126 | S2: 3074579 | T2: 3082448 | U2: 3095344 | V2: 3101621 | W2: 3107100 | X2: 3111630 | Y2: 3115029 | Z2: 3117196 | AA2: 3118092 | AB2: 3117727 | AC2: 3116046
A3: Armenia | C3: ARMN | D3: =UPPER(LEFT(A3,3)) -> ARM | F3: =C3&"TBSP Index" -> ARMNTBSP Index | I3: 3071972 | J3: 3069558 | K3: 3067015 | L3: 3064111 | M3: 3060631 | N3: 3056382 | O3: 3051250 | P3: 3045191 | Q3: 3038217 | R3: 3030288 | S3: 3021324 | T3: 3011222 | U3: 3000756 | V3: 2989091 | W3: 2976765 | X3: 2963837 | Y3: 2950306 | Z3: 2936262 | AA3: 2921860 | AB3: 2907216 | AC3: 2892342
A4: Azerbaijan | C4: AZER | D4: =UPPER(LEFT(A4,3)) -> AZE | F4: =C4&"TBSP Index" -> AZERTBSP Index | I4: 9301673 | J4: 9397279 | K4: 9493600 | L4: 9590159 | M4: 9686210 | N4: 9780780 | O4: 9872765 | P4: 9961396 | Q4: 10046516 | R4: 10128025 | S4: 10205810 | T4: 10279658 | U4: 10559462 | V4: 10604731 | W4: 10650239 | X4: 10694370 | Y4: 10736712 | Z4: 10778564 | AA4: 10819904 | AB4: 10860548 | AC4: 10900586
A5: Bosnia and Herzegovina | C5: BSHE | D5: BIH | F5: =C5&"TBSP Index" -> BSHETBSP Index | I5: 3884899 | J5: 3882359 | K5: 3879296 | L5: 3875723 | M5: 3871643 | N5: 3867055 | O5: 3861912 | P5: 3856181 | Q5: 3849891 | R5: 3843037 | S5: 3835586 | T5: 3827465 | U5: 3816459 | V5: 3807764 | W5: 3798671 | X5: 3789077 | Y5: 3778869 | Z5: 3767946 | AA5: 3756220 | AB5: 3743685 | AC5: 3730292
A6: Bulgaria | C6: BULG | D6: BGR | F6: =C6&"TBSP Index" -> BULGTBSP Index | I6: 7391079 | J6: 7350504 | K6: 7308613 | L6: 7267961 | M6: 7228183 | N6: 7186893 | O6: 7144653 | P6: 7101510 | Q6: 7057504 | R6: 7012640 | S6: 6966899 | T6: 6920315 | U6: 6873253 | V6: 6827736 | W6: 6782659 | X6: 6737997 | Y6: 6693714 | Z6: 6649805 | AA6: 6606303 | AB6: 6563256 | AC6: 6520697
A7: Croatia | C7: CRTA | D7: HRV | F7: =C7&"TBSP Index" -> CRTATBSP Index | I7: 4417475 | J7: 4403676 | K7: 4389754 | L7: 4375160 | M7: 4356748 | N7: 4335285 | O7: 4313911 | P7: 4292667 | Q7: 4271543 | R7: 4250505 | S7: 4229585 | T7: 4208973 | U7: 4188853 | V7: 4169239 | W7: 4150116 | X7: 4131508 | Y7: 4112955 | Z7: 4094087 | AA7: 4075046 | AB7: 4055934 | AC7: 4036866
A8: Czech Republic | C8: CZEC | D8: =UPPER(LEFT(A8,3)) -> CZE | F8: =C8&"TBSP Index" -> CZECTBSP Index | I8: 10550886 | J8: 10573222 | K8: 10587913 | L8: 10591394 | M8: 10602468 | N8: 10623181 | O8: 10643453 | P8: 10671559 | Q8: 10707049 | R8: 10748990 | S8: 10778812 | T8: 10797500 | U8: 10816746 | V8: 10830412 | W8: 10837890 | X8: 10838703 | Y8: 10835323 | Z8: 10830457 | AA8: 10824236 | AB8: 10816841 | AC8: 10808459
A9: Estonia | C9: ESTO | D9: =UPPER(LEFT(A9,3)) -> EST | F9: =C9&"TBSP Index" -> ESTOTBSP Index | I9: 1302817 | J9: 1297236 | K9: 1288868 | L9: 1279726 | M9: 1272393 | N9: 1265255 | O9: 1258272 | P9: 1251222 | Q9: 1243890 | R9: 1236253 | S9: 1228296 | T9: 1220042 | U9: 1211524 | V9: 1202762 | W9: 1193791 | X9: 1184655 | Y9: 1175394 | Z9: 1166047 | AA9: 1156665 | AB9: 1147306 | AC9: 1138017
A10: Georgia | C10: GEOG | D10: =UPPER(LEFT(A10,3)) -> GEO | F10: =C10&"TBSP Index" -> GEOGTBSP Index | I10: 4902939 | J10: 4938340 | K10: 4950269 | L10: 4942158 | M10: 4935889 | N10: 4931249 | O10: 4928106 | P10: 4926448 | Q10: 4926309 | R10: 4927734 | S10: 4930665 | T10: 4933674 | U10: 4935518 | V10: 4927228 | W10: 4900961 | X10: 4877662 | Y10: 4856613 | Z10: 4837299 | AA10: 4819925 | AB10: 4804891 | AC10: 4792455
A11: Hungary | C11: HNGY | D11: =UPPER(LEFT(A11,3)) -> HUN | F11: =C11&"TBSP Index" -> HNGYTBSP Index | I11: 9989465 | J11: 9970530 | K11: 9950567 | L11: 9929530 | M11: 9907419 | N11: 9884329 | O11: 9860398 | P11: 9835682 | Q11: 9810134 | R11: 9783707 | S11: 9756400 | T11: 9728337 | U11: 9699577 | V11: 9885834 | W11: 9855745 | X11: 9827455 | Y11: 9798339 | Z11: 9768324 | AA11: 9737447 | AB11: 9705694 | AC11: 9672981
A12: Latvia | C12: LATV | D12: LVA | F12: =C12&"TBSP Index" -> LATVTBSP Index | I12: 2115339 | J12: 2076493 | K12: 2051103 | L12: 2029430 | M12: 2007714 | N12: 1986717 | O12: 1965848 | P12: 1945078 | Q12: 1924381 | R12: 1903750 | S12: 1883186 | T12: 1862687 | U12: 1842226 | V12: 1821750 | W12: 1801246 | X12: 1780740 | Y12: 1760288 | Z12: 1739920 | AA12: 1719673 | AB12: 1699624 | AC12: 1679841
A13: Lithuania | C13: LITH | D13: LTU | F13: =C13&"TBSP Index" -> LITHTBSP Index | I13: 3088773 | J13: 3015011 | K13: 2973159 | L13: 2943358 | M13: 2914439 | N13: 2884632 | O13: 2855139 | P13: 2825940 | Q13: 2797002 | R13: 2768295 | S13: 2739816 | T13: 2711566 | U13: 2683546 | V13: 2655755 | W13: 2628186 | X13: 2600838 | Y13: 2573717 | Z13: 2546846 | AA13: 2520267 | AB13: 2494042 | AC13: 2468224
A14: Macedonia | C14: MCDN | D14: MKD | F14: =C14&"TBSP Index" -> MCDNTBSP Index | I14: 2072086 | J14: 2077328 | K14: 2082370 | L14: 2087171 | M14: 2091719 | N14: 2096015 | O14: 2100025 | P14: 2103721 | Q14: 2107091 | R14: 2110113 | S14: 2112774 | T14: 2115028 | U14: 2116845 | V14: 2118212 | W14: 2119101 | X14: 2119511 | Y14: 2119419 | Z14: 2118797 | AA14: 2117650 | AB14: 2116000 | AC14: 2113860
A15: Moldova | C15: MLDV | D15: MDA | F15: =C15&"TBSP Index" -> MLDVTBSP Index | I15: 3920438 | J15: 3914098 | K15: 3907889 | L15: 3901481 | M15: 3881027 | N15: 3847644 | O15: 3801856 | P15: 3740498 | Q15: 3680426 | R15: 3626590 | S15: 3587186 | T15: 3563449 | U15: 3592090 | V15: 3620399 | W15: 3599528 | X15: 3578930 | Y15: 3558465 | Z15: 3537962 | AA15: 3517391 | AB15: 3496765 | AC15: 3476121
A16: Montenegro | C16: MNTN | D16: MNE | F16: =C16&"TBSP Index" -> MNTNTBSP Index | I16: 622553 | J16: 622433 | K16: 622079 | L16: 621603 | M16: 620897 | N16: 619723 | O16: 618126 | P16: 616284 | Q16: 614229 | R16: 612064 | S16: 609786 | T16: 607414 | U16: 604966 | V16: 602445 | W16: 599849 | X16: 597174 | Y16: 594406 | Z16: 591525 | AA16: 588514 | AB16: 585362 | AC16: 582062
A17: Poland | C17: PNDO | D17: =UPPER(LEFT(A17,3)) -> POL | F17: =C17&"TBSP Index" -> PNDOTBSP Index | I17: 38616395 | J17: 38631804 | K17: 38632128 | L17: 38618538 | M17: 38592156 | N17: 38559087 | O17: 38518526 | P17: 38469803 | Q17: 38412361 | R17: 38345891 | S17: 38270292 | T17: 38185913 | U17: 38093101 | V17: 37991766 | W17: 38746310 | X17: 38364679 | Y17: 38006623 | Z17: 37684317 | AA17: 37399443 | AB17: 37153792 | AC17: 36949646
A18: Romania | C18: ROMA | D18: ROU | F18: =C18&"TBSP Index" -> ROMATBSP Index | I18: 21959278 | J18: 21904551 | K18: 21848504 | L18: 21790479 | M18: 21729871 | N18: 21666350 | O18: 21599736 | P18: 21529967 | Q18: 21457116 | R18: 21381356 | S18: 21302893 | T18: 21221688 | U18: 21137787 | V18: 21051452 | W18: 20962858 | X18: 20872127 | Y18: 20779194 | Z18: 20684068 | AA18: 20587055 | AB18: 20488470 | AC18: 20388581
A19: Serbia | C19: SERB | D19: SRB | F19: =C19&"TBSP Index" -> SERBTBSP Index | I19: 7233391 | J19: 7195769 | K19: 7159029 | L19: 7124084 | M19: 7089319 | N19: 7052916 | O19: 7015855 | P19: 6978391 | Q19: 6940138 | R19: 6902768 | S19: 6856660 | T19: 6796857 | U19: 6739471 | V19: 6693375 | W19: 6652212 | X19: 6612318 | Y19: 6573488 | Z19: 6535467 | AA19: 6497944 | AB19: 6460689 | AC19: 6423523
A20: Slovakia | C20: SLVK | D20: SVK | F20: =C20&"TBSP Index" -> SLVKTBSP Index | I20: 5426036 | J20: 5433273 | K20: 5440777 | L20: 5446591 | M20: 5451848 | N20: 5456999 | O20: 5463996 | P20: 5472430 | Q20: 5479969 | R20: 5487346 | S20: 5492134 | T20: 5487789 | U20: 5527637 | V20: 5569395 | W20: 5563649 | X20: 5559451 | Y20: 5554882 | Z20: 5548912 | AA20: 5541484 | AB20: 5532691 | AC20: 5522701
A21: Slovenia | C21: SLVN | D21: SVN | F21: =C21&"TBSP Index" -> SLVNTBSP Index | I21: 2084182 | J21: 2088442 | K21: 2092758 | L21: 2095552 | M21: 2097579 | N21: 2099131 | O21: 2100372 | P21: 2101369 | Q21: 2102031 | R21: 2102381 | S21: 2102452 | T21: 2102106 | U21: 2101208 | V21: 2099790 | W21: 2097893 | X21: 2095577 | Y21: 2092892 | Z21: 2089872 | AA21: 2086563 | AB21: 2083023 | AC21: 2079316
A22: TOTAL | I22: =SUM(I2:I21) -> 144938628 | J22: =SUM(J2:J21) -> 144836573 | K22: =SUM(K2:K21) -> 144728550 | L22: =SUM(L2:L21) -> 144585614 | M22: =SUM(M2:M21) -> 144418362 | N22: =SUM(N2:N21) -> 144228901 | O22: =SUM(O2:O21) -> 144012793 | P22: =SUM(P2:P21) -> 143773324 | ... AC22: =SUM(AC2:AC21) -> 139292616
A24: Seats | I24: 2010 | J24: 2011 | K24: 2012 | L24: 2013 | M24: 2014 | N24: 2015 | O24: 2016 | P24: 2017 | Q24: 2018 | R24: 2019 | S24: 2020 | T24: 2021 | U24: 2022 | V24: 2023 | W24: 2024 | X24: 2025 | Y24: 2026 | Z24: 2027 | AA24: 2028 | AB24: 2029 | AC24: 2030
A25: Albania | I25: 939973 | J25: 1016377 | K25: 1034693 | L25: 1074295 | M25: 1076399 | N25: 1005911 | O25: 1049370 | P25: 1404488 | Q25: 1787188 | R25: 2016476 | S25: 1859720 | T25: 2521213 | U25: 3164131 | V25: 4326635 | W25: 6442851 | X25: 6638559
A26: Armenia | I26: 1144007 | J26: 1145954 | K26: 1238707 | L26: 1169057 | M26: 1361498 | N26: 1220497 | O26: 1232165 | P26: 1387372 | Q26: 1754727 | R26: 1830899 | S26: 893952 | T26: 1290705 | U26: 1335620 | V26: 2182214 | W26: 2168187 | X26: 2792403
A27: Azerbaijan | I27: 1471435 | J27: 1618800 | K27: 1739125 | L27: 1822582 | M27: 2000839 | N27: 1968885 | O27: 2086825 | P27: 2214656 | Q27: 2460343 | R27: 2491343 | S27: 890060 | T27: 981579 | U27: 1991799 | V27: 3034856 | W27: 3833041 | X27: 3838236
A28: Bosnia and Herzegovina | I28: 272689 | J28: 300011 | K28: 286730 | L28: 401892 | M28: 468793 | N28: 564655 | O28: 660608 | P28: 868102 | Q28: 941372 | R28: 1067487 | S28: 613823 | T28: 907541 | U28: 1401164 | V28: 1393611 | W28: 1419154 | X28: 1884024
A29: Bulgaria | I29: 2482073 | J29: 2496816 | K29: 2507896 | L29: 3076063 | M29: 3226687 | N29: 3409414 | O29: 4232071 | P29: 5355234 | Q29: 6078650 | R29: 5961213 | S29: 3562353 | T29: 3651665 | U29: 5004597 | V29: 5831305 | W29: 5988612 | X29: 6669189
A30: Croatia | I30: 2421019 | J30: 2441660 | K30: 2593664 | L30: 3038151 | M30: 3245337 | N30: 3485300 | O30: 3919946 | P30: 4672442 | Q30: 5167248 | R30: 5679959 | S30: 1639083 | T30: 3010186 | U30: 5682655 | V30: 5907399 | W30: 7175672 | X30: 8024864
A31: Czech Republic | I31: 6245306 | J31: 6494963 | K31: 6016434 | L31: 6144155 | M31: 6091940 | N31: 6666895 | O31: 7104327 | P31: 8226835 | Q31: 9265068 | R31: 9634047 | S31: 3116214 | T31: 3075645 | U31: 5917244 | V31: 8189106 | W31: 8852441 | X31: 10128232
A32: Estonia | I32: 622568 | J32: 802435 | K32: 572009 | L32: 513089 | M32: 535804 | N32: 644357 | O32: 687670 | P32: 720429 | Q32: 761686 | R32: 971621 | S32: 648006 | T32: 710692 | U32: 1358718 | V32: 1338912 | W32: 1638731 | X32: 1687400
A33: Georgia | I33: 685582 | J33: 777465 | K33: 871297 | L33: 1216478 | M33: 1255737 | N33: 1431545 | O33: 1710468 | P33: 2352669 | Q33: 2999332 | R33: 3168924 | S33: 1092691 | T33: 1844895 | U33: 2627910 | V33: 3599112 | W33: 4067594 | X33: 4646740
A34: Hungary | I34: 4612786 | J34: 4807258 | K34: 4741493 | L34: 4965055 | M34: 5016466 | N34: 5757408 | O34: 6553382 | P34: 7248871 | Q34: 8273216 | R34: 8988876 | S34: 4781772 | T34: 3351127 | U34: 7364375 | V34: 8210485 | W34: 9627811 | X34: 10680110
A35: Latvia | I35: 2673517 | J35: 2364348 | K35: 2237580 | L35: 2209696 | M35: 2069783 | N35: 2259944 | O35: 2212938 | P35: 2412074 | Q35: 2987354 | R35: 3513317 | S35: 1874928 | T35: 2071177 | U35: 3515684 | V35: 3970989 | W35: 4112539 | X35: 4107399
A36: Lithuania | I36: 1075485 | J36: 1214469 | K36: 1493956 | L36: 1626705 | M36: 1671397 | N36: 1908577 | O36: 2162034 | P36: 2402387 | Q36: 2867647 | R36: 2965985 | S36: 1663282 | T36: 1696151 | U36: 2815625 | V36: 2819864 | W36: 3241145 | X36: 3567206
... A44: Slovenia | I44: 274200 | J44: 333612 | K44: 220415 | L44: 281764 | M44: 273434 | N44: 351672 | O44: 378903 | P44: 452821 | Q44: 631781 | R44: 655058 | S44: 157377 | T44: 184439 | U44: 439597 | V44: 538242 | W44: 655335 | X44: 779112
A45: TOTAL | I45: =SUM(I25:I44) -> 43110214 | J45: =SUM(J25:J44) -> 44062821 | K45: =SUM(K25:K44) -> 45315140 | L45: =SUM(L25:L44) -> 49101144 | M45: =SUM(M25:M44) -> 51346430 | N45: =SUM(N25:N44) -> 57918244 | O45: =SUM(O25:O44) -> 64918327 | P45: =SUM(P25:P44) -> 76296513 | ... X45: =SUM(X25:X44) -> 125495551
A47: Seat growth | J47: =J45/I45-1 -> 0.022097014 | K47: =K45/J45-1 -> 0.028421217 | L47: =L45/K45-1 -> 0.083548324 | M47: =M45/L45-1 -> 0.045727774 | N47: =N45/M45-1 -> 0.1279897 | O47: =O45/N45-1 -> 0.12086145 | P47: =P45/O45-1 -> 0.17526924 | Q47: =Q45/P45-1 -> 0.13929827 | ... X47: =X45/W45-1 -> 0.13969415
A49: Seats per capita | I49: 2010 | J49: 2011 | K49: 2012 | L49: 2013 | M49: 2014 | N49: 2015 | O49: 2016 | P49: 2017 | Q49: 2018 | R49: 2019 | S49: 2020 | T49: 2021 | U49: 2022 | V49: 2023 | W49: 2024 | X49: 2025 | Y49: 2026 | Z49: 2027 | AA49: 2028 | AB49: 2029 | AC49: 2030
A51: TOTAL | I51: =I45/I22 -> 0.29743771 | J51: =J45/J22 -> 0.30422441 | K51: =K45/K22 -> 0.31310436 | L51: =L45/L22 -> 0.3395991 | M51: =M45/M22 -> 0.35553948 | N51: =N45/N22 -> 0.40157169 | O51: =O45/O22 -> 0.45078167 | P51: =P45/P22 -> 0.53067225 | ... X51: =X45/X22 -> 0.88167138
...
